<?xml version="1.0" encoding="utf-8"?>
<!-- =================================================================================== -->
<!-- |    This document was autogenerated by xacro from vacuum_bot.urdf.xacro          | -->
<!-- |    EDITING THIS FILE BY HAND IS NOT RECOMMENDED                                 | -->
<!-- =================================================================================== -->
<robot name="vacuum_bot" xmlns:xacro="http://www.ros.org/wiki/xacro">
  <!-- include constants, configs, meshes etc -->
  <!-- math constants -->
  <!-- robot properties -->
  <!-- math constants -->
  <!-- robot properties -->
  <!-- macro for fast collision box primitive (lots of them in the model) -->
  <!-- macro for fast collision cylinder primitive (lots of them in the model) -->
  <!-- Gazebo transmission_block macro -->
  <!-- Macro for initiallizing the ros_control plugin -->
  <!-- macro for odometry publishing -->
  <!-- Robot creation macro -->
  <link name="base_footprint"/>
  <joint name="foot_base_joint" type="fixed">
    <origin rpy="0 0 0" xyz="0 0 0.015"/>
    <parent link="base_footprint"/>
    <child link="base_link"/>
  </joint>
  <link name="base_link">
    <visual>
      <origin rpy="0 0 0" xyz="0 0 0"/>
      <geometry>
        <mesh filename="package://vacuum_bot/urdf/meshes/base_tex.dae"/>
      </geometry>
    </visual>
    <collision>
      <geometry>
        <mesh filename="package://vacuum_bot/urdf/meshes/base_collision.dae"/>
      </geometry>
      <origin xyz="0 0 0"/>
    </collision>
    <collision>
      <geometry>
        <cylinder length="0.07" radius="0.18"/>
      </geometry>
      <origin rpy="0 0 0" xyz="0 0 0.035"/>
    </collision>
    <inertial>
      <mass value="27.84"/>
      <inertia ixx="0.37267" ixy="0.535" ixz="0.27612" iyy="0.60173" iyz="0.37267" izz="0.5256"/>
    </inertial>
  </link>
  <link name="rwheel">
    <visual>
      <origin rpy="0 0 0" xyz="0 0 0"/>
      <geometry>
        <mesh filename="package://vacuum_bot/urdf/meshes/wheel_tex.dae"/>
      </geometry>
    </visual>
    <collision>
      <geometry>
        <cylinder length="0.005" radius="0.03"/>
      </geometry>
      <origin rpy="0 0 0" xyz="0 0 0"/>
    </collision>
    <inertial>
      <mass value="0.0482"/>
      <origin xyz="0 0 0"/>
      <inertia ixx="3.745e-7" ixy="6.657e-7" ixz="3.28e-7" iyy="3.28e-7" iyz="3.745e-7" izz="6.657e-7"/>
    </inertial>
  </link>
  <joint name="base_footprint_rwheel_joint" type="fixed">
    <axis rpy="0 0 0" xyz="0 0 1"/>
    <origin rpy="1.570796325 0 0" xyz="0.085 -0.09 0.03"/>
    <parent link="base_footprint"/>
    <child link="rwheel"/>
  </joint>
  <link name="lwheel">
    <visual>
      <origin rpy="0 0 0" xyz="0 0 0"/>
      <geometry>
        <mesh filename="package://vacuum_bot/urdf/meshes/wheel_tex.dae"/>
      </geometry>
    </visual>
    <collision>
      <geometry>
        <cylinder length="0.005" radius="0.03"/>
      </geometry>
      <origin rpy="0 0 0" xyz="0 0 0"/>
    </collision>
    <inertial>
      <mass value="0.0482"/>
      <origin xyz="0 0 0"/>
      <inertia ixx="3.745e-7" ixy="6.657e-7" ixz="3.28e-7" iyy="3.28e-7" iyz="3.745e-7" izz="6.657e-7"/>
    </inertial>
  </link>
  <joint name="base_footprint_lwheel_joint" type="fixed">
    <axis rpy="0 0 0" xyz="0 0 1"/>
    <origin rpy="1.570796325 0 0" xyz="0.085 0.09 0.03"/>
    <parent link="base_footprint"/>
    <child link="lwheel"/>
  </joint>
  <link name="wheelturn_link">
    <visual>
      <origin rpy="0 0 0" xyz="0 0 0"/>
      <geometry>
        <mesh filename="package://vacuum_bot/urdf/meshes/wheel_plate.dae"/>
      </geometry>
    </visual>
    <collision>
      <geometry>
        <cylinder length="0.002" radius="0.0675"/>
      </geometry>
      <origin rpy="0 0 0" xyz="0 0 0"/>
    </collision>
    <inertial>
      <mass value="0.2102"/>
      <inertia ixx="2.56e-7" ixy="4.979e-7" ixz="2.425e-7" iyy="2.425e-7" iyz="3.745e-7" izz="6.657e-7"/>
    </inertial>
  </link>
  <joint name="base_footprint_wheelturn_joint" type="continuous">
    <axis rpy="0 0 3.14159265" xyz="0 0 1"/>
    <origin xyz="-0.09 0 0.015"/>
    <parent link="base_footprint"/>
    <child link="wheelturn_link"/>
  </joint>
  <link name="freewheel">
    <visual>
      <origin rpy="0 0 0" xyz="0 0 0"/>
      <geometry>
        <mesh filename="package://vacuum_bot/urdf/meshes/wheel_tex.dae"/>
      </geometry>
    </visual>
    <collision>
      <geometry>
        <cylinder length="0.005" radius="0.03"/>
      </geometry>
      <origin rpy="0 0 0" xyz="0 0 0"/>
    </collision>
    <inertial>
      <mass value="0.0482"/>
      <origin xyz="0 0 0"/>
      <inertia ixx="3.745e-7" ixy="6.657e-7" ixz="3.28e-7" iyy="3.28e-7" iyz="3.745e-7" izz="6.657e-7"/>
    </inertial>
  </link>
  <joint name="wheelturn_link_freewheel_joint" type="fixed">
    <axis rpy="0 0 0" xyz="0 0 1"/>
    <origin rpy="1.570796325 0 0" xyz="-0.025 0 0.015"/>
    <parent link="wheelturn_link"/>
    <child link="freewheel"/>
  </joint>
  <link name="z_link">
    <visual>
      <origin rpy="0 0 1.570796325" xyz="0 0 0"/>
      <geometry>
        <mesh filename="package://vacuum_bot/urdf/meshes/z_link_tex.dae"/>
      </geometry>
    </visual>
    <collision>
      <geometry>
        <cylinder length="0.115" radius="0.01"/>
      </geometry>
      <origin rpy="0 0 0" xyz="0 0 0"/>
    </collision>
    <collision>
      <geometry>
        <cylinder length="0.085" radius="0.025"/>
      </geometry>
      <origin rpy="0 0 0" xyz="0 0 0"/>
    </collision>
    <inertial>
      <mass value="0.092245"/>
      <inertia ixx="5.697e-8" ixy="3.451e-8" ixz="5.343e-8" iyy="5.343e-8" iyz="3.451e-8" izz="3.451e-8"/>
    </inertial>
  </link>
  <joint name="base_z_joint" type="revolute">
    <axis rpy="0 0 0" xyz="0 0 1"/>
    <origin rpy="0 0 1.570796325" xyz="0.0295 0.095 0.06"/>
    <parent link="base_link"/>
    <child link="z_link"/>
    <limit effort="1000.0" lower="-3.14159265" upper="3.14159265" velocity="0.5"/>
    <dynamics damping="0.7" friction="1.0"/>
  </joint>
  <link name="lower_arm">
    <visual>
      <origin rpy="0 0 0" xyz="0 0 0"/>
      <geometry>
        <mesh filename="package://vacuum_bot/urdf/meshes/lower_arm_tex.dae"/>
      </geometry>
    </visual>
    <collision>
      <geometry>
        <box size="0.168 0.01 0.01"/>
      </geometry>
      <origin xyz="0.09 0 0.0235"/>
    </collision>
    <collision>
      <geometry>
        <box size="0.168 0.01 0.01"/>
      </geometry>
      <origin xyz="0.09 0 -0.0235"/>
    </collision>
    <collision>
      <geometry>
        <box size="0.005 0.02 0.02"/>
      </geometry>
      <origin xyz="0.178 -0.025 0"/>
    </collision>
    <collision>
      <geometry>
        <cylinder length="0.058" radius="0.014"/>
      </geometry>
      <origin rpy="0 0 1.570796325" xyz="0 0 0"/>
    </collision>
    <collision>
      <geometry>
        <cylinder length="0.058" radius="0.015"/>
      </geometry>
      <origin rpy="0 0 1.570796325" xyz="0.178 0 0"/>
    </collision>
    <inertial>
      <mass value="0.027199"/>
      <inertia ixx="0.01" ixy="0" ixz="0" iyy="0.01" iyz="0" izz="0.01"/>
    </inertial>
  </link>
  <joint name="z_lower_joint" type="revolute">
    <axis rpy="0 0 0" xyz="0 0 1"/>
    <origin rpy="1.570796325 -1.570796325 0" xyz="0 0 0.025"/>
    <parent link="z_link"/>
    <child link="lower_arm"/>
    <limit effort="1000.0" lower="-3.14159265" upper="3.14159265" velocity="0.5"/>
    <dynamics damping="0.7" friction="1.0"/>
  </joint>
  <link name="upper_arm">
    <visual>
      <origin rpy="0 0 0" xyz="0 0 0"/>
      <geometry>
        <mesh filename="package://vacuum_bot/urdf/meshes/upper_arm_tex.dae"/>
      </geometry>
    </visual>
    <collision>
      <geometry>
        <box size="0.174 0.01 0.01"/>
      </geometry>
      <origin xyz="0.0775 0 0.0235"/>
    </collision>
    <collision>
      <geometry>
        <box size="0.174 0.01 0.01"/>
      </geometry>
      <origin xyz="0.0775 0 -0.0235"/>
    </collision>
    <collision>
      <geometry>
        <box size="0.005 0.02 0.02"/>
      </geometry>
      <origin xyz="0 0.025 0"/>
    </collision>
    <collision>
      <geometry>
        <cylinder length="0.058" radius="0.015"/>
      </geometry>
      <origin rpy="0 0 1.570796325" xyz="0 0 0"/>
    </collision>
    <collision>
      <geometry>
        <cylinder length="0.011" radius="0.015"/>
      </geometry>
      <origin rpy="0 0 1.570796325" xyz="0.178 0 0.0235"/>
    </collision>
    <collision>
      <geometry>
        <cylinder length="0.011" radius="0.015"/>
      </geometry>
      <origin rpy="0 0 1.570796325" xyz="0.178 0 -0.0235"/>
    </collision>
    <inertial>
      <mass value="0.05571"/>
      <inertia ixx="0.01" ixy="0" ixz="2.975e-8" iyy="0.01" iyz="0" izz="0.01"/>
    </inertial>
  </link>
  <joint name="lower_upper_joint" type="revolute">
    <axis rpy="0 0 0" xyz="0 0 1"/>
    <origin rpy="0 0 0" xyz="0.178 0 -0.059"/>
    <parent link="lower_arm"/>
    <child link="upper_arm"/>
    <limit effort="1000.0" lower="-3.14159265" upper="3.14159265" velocity="0.5"/>
    <dynamics damping="0.7" friction="1.0"/>
  </joint>
  <link name="end_effector">
    <visual>
      <origin rpy="0 0 0" xyz="0 0 0"/>
      <geometry>
        <mesh filename="package://vacuum_bot/urdf/meshes/end_effector_tex.dae"/>
      </geometry>
    </visual>
    <collision>
      <geometry>
        <cylinder length="0.0355" radius="0.015"/>
      </geometry>
      <origin rpy="0 0 0" xyz="0 0 0"/>
    </collision>
    <collision>
      <geometry>
        <cylinder length="0.043" radius="0.01"/>
      </geometry>
      <origin rpy="0 1.570796325 0" xyz="0.006 0 0"/>
    </collision>
    <inertial>
      <mass value="0.19306"/>
      <inertia ixx="0.01" ixy="2.919e-8" ixz="9.708e-8" iyy="0.01" iyz="9.034e-8" izz="0.01"/>
    </inertial>
  </link>
  <joint name="upper_end_joint" type="revolute">
    <axis rpy="0 0 0" xyz="0 0 1"/>
    <origin rpy="0 0 0" xyz="0.178 0 0"/>
    <parent link="upper_arm"/>
    <child link="end_effector"/>
    <limit effort="1000.0" lower="-3.14159265" upper="3.14159265" velocity="1"/>
    <dynamics damping="0.7" friction="1.0"/>
  </joint>
  <link name="virtual_end">
    <visual>
      <origin rpy="0 0 0" xyz="0 0 -0.028"/>
      <geometry>
        <box size="0.001 0.001 0.001"/>
      </geometry>
    </visual>
    <collision>
      <geometry>
        <box size="0.001 0.001 0.001"/>
      </geometry>
      <origin xyz="0 0 -0.028"/>
    </collision>
    <inertial>
      <mass value="0.001"/>
      <inertia ixx="0.001" ixy="0" ixz="0" iyy="0.001" iyz="0" izz="0.001"/>
    </inertial>
  </link>
  <joint name="end_virtual_joint" type="fixed">
    <axis rpy="0 0 0" xyz="0 0 1"/>
    <origin rpy="1.570796325 0 1.570796325" xyz="0.028 0.0 0"/>
    <parent link="end_effector"/>
    <child link="virtual_end"/>
    <limit effort="1000" velocity="0"/>
  </joint>
  <link name="camera_back_model">
    <visual>
      <origin rpy="0 0 0" xyz="0 0 0"/>
      <geometry>
        <mesh filename="package://vacuum_bot/urdf/meshes/camera.dae"/>
      </geometry>
    </visual>
    <collision>
      <origin rpy="0 0 0" xyz="0 0 0"/>
      <geometry>
        <mesh filename="package://vacuum_bot/urdf/meshes/camera.dae"/>
      </geometry>
    </collision>
    <inertial>
      <mass value="0.01"/>
      <inertia ixx="0.01" ixy="0" ixz="0" iyy="0.01" iyz="0" izz="0"/>
    </inertial>
  </link>
  <joint name="camera_back_model_joint" type="fixed">
    <axis rpy="0 0 0" xyz="1 0 0"/>
    <origin rpy="0 -0.5 0" xyz="-0.16 0 0.1"/>
    <child link="camera_back_model"/>
    <parent link="base_footprint"/>
  </joint>
  <link name="camera_front_model">
    <visual>
      <origin rpy="0 0 0" xyz="0 0 0"/>
      <geometry>
        <mesh filename="package://vacuum_bot/urdf/meshes/camera.dae"/>
      </geometry>
    </visual>
    <collision>
      <origin rpy="0 0 0" xyz="0 0 0"/>
      <geometry>
        <mesh filename="package://vacuum_bot/urdf/meshes/camera.dae"/>
      </geometry>
    </collision>
    <inertial>
      <mass value="0.01"/>
      <inertia ixx="0.01" ixy="0" ixz="0" iyy="0.01" iyz="0" izz="0"/>
    </inertial>
  </link>
  <joint name="camera_front_model_joint" type="fixed">
    <axis rpy="0 0 0" xyz="1 0 0"/>
    <origin rpy="0 -0.5 3.14159265" xyz="0.16 0 0.1"/>
    <child link="camera_front_model"/>
    <parent link="base_footprint"/>
  </joint>
  <link name="camera_side_model">
    <visual>
      <origin rpy="0 0 0" xyz="0 0 0"/>
      <geometry>
        <mesh filename="package://vacuum_bot/urdf/meshes/camera.dae"/>
      </geometry>
    </visual>
    <collision>
      <origin rpy="0 0 0" xyz="0 0 0"/>
      <geometry>
        <mesh filename="package://vacuum_bot/urdf/meshes/camera.dae"/>
      </geometry>
    </collision>
    <inertial>
      <mass value="0.01"/>
      <inertia ixx="0.01" ixy="0" ixz="0" iyy="0.01" iyz="0" izz="0"/>
    </inertial>
  </link>
  <joint name="camera_side_model_joint" type="fixed">
    <axis rpy="0 0 0" xyz="1 0 0"/>
    <origin rpy="0 -0.5 1.570796325" xyz="0 -0.16 0.1"/>
    <child link="camera_side_model"/>
    <parent link="base_footprint"/>
  </joint>
  <link name="camera_outwards_model">
    <visual>
      <origin rpy="0 0 0" xyz="0 0 0"/>
      <geometry>
        <mesh filename="package://vacuum_bot/urdf/meshes/camera.dae"/>
      </geometry>
    </visual>
    <collision>
      <origin rpy="0 0 0" xyz="0 0 0"/>
      <geometry>
        <mesh filename="package://vacuum_bot/urdf/meshes/camera.dae"/>
      </geometry>
    </collision>
    <inertial>
      <mass value="0.01"/>
      <inertia ixx="0.01" ixy="0" ixz="0" iyy="0.01" iyz="0" izz="0"/>
    </inertial>
  </link>
  <joint name="camera_outwards_model_joint" type="fixed">
    <axis rpy="0 0 0" xyz="1 0 0"/>
    <origin rpy="0 0 0" xyz="0.165 0 0.1"/>
    <child link="camera_outwards_model"/>
    <parent link="base_footprint"/>
  </joint>
  <!-- Cameras for scene capturing -->
  <link name="camera_end_link"/>
  <joint name="camera_end_joint" type="fixed">
    <axis rpy="0 0 0" xyz="1 0 0"/>
    <origin rpy="-1.570796325 0 -0.4" xyz="0.017 0.015 -0.0175"/>
    <parent link="end_effector"/>
    <child link="camera_end_link"/>
  </joint>
  <gazebo reference="camera_end_link">
    <sensor name="camera_end" type="camera">
      <update_rate>50</update_rate>
      <camera name="head">
        <horizontal_fov>1.3962634</horizontal_fov>
        <image>
          <width>1920</width>
          <height>1080</height>
          <format>R8G8B8</format>
        </image>
        <clip>
          <near>0.01</near>
          <far>300</far>
        </clip>
      </camera>
      <plugin filename="libgazebo_ros_camera.so" name="camera_controller">
        <alwaysOn>true</alwaysOn>
        <updateRate>0.0</updateRate>
        <cameraName>vacuum_bot/camera_end</cameraName>
        <imageTopicName>image_raw</imageTopicName>
        <cameraInfoTopicName>camera_info</cameraInfoTopicName>
        <frameName>camera_link</frameName>
        <hackBaseline>0.07</hackBaseline>
        <distortionK1>0.0</distortionK1>
        <distortionK2>0.0</distortionK2>
        <distortionK3>0.0</distortionK3>
        <distortionT1>0.0</distortionT1>
        <distortionT2>0.0</distortionT2>
      </plugin>
    </sensor>
  </gazebo>
  <link name="camera_front_link"/>
  <joint name="camera_front_joint" type="fixed">
    <axis rpy="0 0 0" xyz="1 0 0"/>
    <origin rpy="0 0.2 0" xyz="0.11 0 0.12"/>
    <parent link="base_link"/>
    <child link="camera_front_link"/>
  </joint>
  <gazebo reference="camera_front_link">
    <sensor name="camera_front" type="camera">
      <update_rate>50</update_rate>
      <camera name="head">
        <horizontal_fov>1.3962634</horizontal_fov>
        <image>
          <width>1920</width>
          <height>1080</height>
          <format>R8G8B8</format>
        </image>
        <clip>
          <near>0.01</near>
          <far>300</far>
        </clip>
      </camera>
      <plugin filename="libgazebo_ros_camera.so" name="camera_controller">
        <alwaysOn>true</alwaysOn>
        <updateRate>0.0</updateRate>
        <cameraName>vacuum_bot/camera_front</cameraName>
        <imageTopicName>image_raw</imageTopicName>
        <cameraInfoTopicName>camera_info</cameraInfoTopicName>
        <frameName>camera_link</frameName>
        <hackBaseline>0.07</hackBaseline>
        <distortionK1>0.0</distortionK1>
        <distortionK2>0.0</distortionK2>
        <distortionK3>0.0</distortionK3>
        <distortionT1>0.0</distortionT1>
        <distortionT2>0.0</distortionT2>
      </plugin>
    </sensor>
  </gazebo>
  <link name="camera_bird_link"/>
  <joint name="camera_bird_joint" type="fixed">
    <axis rpy="0 0 0" xyz="1 0 0"/>
    <origin rpy="0 0.3 2.86" xyz="0.75 -0.375 0.375"/>
    <parent link="base_link"/>
    <child link="camera_bird_link"/>
  </joint>
  <gazebo reference="camera_bird_link">
    <sensor name="camera_bird" type="camera">
      <update_rate>50</update_rate>
      <camera name="head">
        <horizontal_fov>1.3962634</horizontal_fov>
        <image>
          <width>1920</width>
          <height>1080</height>
          <format>R8G8B8</format>
        </image>
        <clip>
          <near>0.01</near>
          <far>300</far>
        </clip>
      </camera>
      <plugin filename="libgazebo_ros_camera.so" name="camera_controller">
        <alwaysOn>true</alwaysOn>
        <updateRate>0.0</updateRate>
        <cameraName>vacuum_bot/camera_bird</cameraName>
        <imageTopicName>image_raw</imageTopicName>
        <cameraInfoTopicName>camera_info</cameraInfoTopicName>
        <frameName>camera_link</frameName>
        <hackBaseline>0.07</hackBaseline>
        <distortionK1>0.0</distortionK1>
        <distortionK2>0.0</distortionK2>
        <distortionK3>0.0</distortionK3>
        <distortionT1>0.0</distortionT1>
        <distortionT2>0.0</distortionT2>
      </plugin>
    </sensor>
  </gazebo>
  <!-- Gazebo plugin publishing the ground truth odometry -->
  <gazebo>
    <plugin filename="libgazebo_ros_p3d.so" name="ground_truth">
      <frameName>map</frameName>
      <bodyName>base_footprint</bodyName>
      <topicName>vacuum_bot/odom</topicName>
      <updateRate>500</updateRate>
    </plugin>
  </gazebo>
  <!-- Transmissions and plugin for ros_control -->
  <transmission name="trans_base_z_joint">
    <type>transmission_interface/SimpleTransmission</type>
    <joint name="base_z_joint">
      <hardwareInterface>hardware_interface/PositionJointInterface</hardwareInterface>
    </joint>
    <actuator name="base_z_joint_motor">
      <hardwareInterface>hardware_interface/PositionJointInterface</hardwareInterface>
      <mechanicalReduction>1</mechanicalReduction>
    </actuator>
  </transmission>
  <transmission name="trans_z_lower_joint">
    <type>transmission_interface/SimpleTransmission</type>
    <joint name="z_lower_joint">
      <hardwareInterface>hardware_interface/PositionJointInterface</hardwareInterface>
    </joint>
    <actuator name="z_lower_joint_motor">
      <hardwareInterface>hardware_interface/PositionJointInterface</hardwareInterface>
      <mechanicalReduction>1</mechanicalReduction>
    </actuator>
  </transmission>
  <transmission name="trans_lower_upper_joint">
    <type>transmission_interface/SimpleTransmission</type>
    <joint name="lower_upper_joint">
      <hardwareInterface>hardware_interface/PositionJointInterface</hardwareInterface>
    </joint>
    <actuator name="lower_upper_joint_motor">
      <hardwareInterface>hardware_interface/PositionJointInterface</hardwareInterface>
      <mechanicalReduction>1</mechanicalReduction>
    </actuator>
  </transmission>
  <transmission name="trans_upper_end_joint">
    <type>transmission_interface/SimpleTransmission</type>
    <joint name="upper_end_joint">
      <hardwareInterface>hardware_interface/PositionJointInterface</hardwareInterface>
    </joint>
    <actuator name="upper_end_joint_motor">
      <hardwareInterface>hardware_interface/PositionJointInterface</hardwareInterface>
      <mechanicalReduction>1</mechanicalReduction>
    </actuator>
  </transmission>
  <gazebo>
    <plugin filename="libgazebo_ros_control.so" name="gazebo_ros_control">
      <robotNamespace>vacuum_bot</robotNamespace>
    </plugin>
  </gazebo>
</robot>
