<?xml version="1.0" encoding="utf-8" ?>
<robot xmlns:xacro="http://www.ros.org/wiki/xacro" name="vacuum_bot">

  <!-- include constants, configs, meshes etc -->
 
  <xacro:include filename="$(find vacuum_bot)/urdf/vacuum_bot_properties.xacro"/>

  <xacro:include filename="$(find vacuum_bot)/urdf/vacuum_bot_macros.xacro"/>

  <!-- Robot creation macro -->

  <xacro:macro name="vacuum_bot">

    <link name="base_footprint"/>

    <joint name="foot_base_joint" type="fixed">
      <origin xyz="0 0 0.015" rpy="0 0 0"/>
      <parent link="base_footprint"/>
      <child link="base_link"/>
    </joint>

    <link name="base_link">
      <visual>
	      <origin xyz="0 0 0" rpy="0 0 0"/>
        <geometry>
          <mesh filename="${base_mesh}"/>
        </geometry>
      </visual>
      
      <collision>
        <geometry>
	  <mesh filename="${base_collision}"/>
        </geometry>
	<origin xyz="0 0 0"/>
      </collision>
      <xacro:collision_cylinder radius="0.18" length="0.07" xyz="0 0 0.035"/>
      
      <inertial>
        <mass value="27.84" />
        <inertia ixx="0.37267" ixy="0.535" ixz="0.27612" iyy="0.60173" iyz="0.37267" izz="0.5256" />
      </inertial>
    </link>

    <xacro:wheel name="rwheel" parent="base_footprint" joint_xyz="0.085 -0.09 0.03" joint_rpy="${PI/2} 0 0"/>
    
    <xacro:wheel name="lwheel" parent="base_footprint" joint_xyz="0.085 0.09 0.03" joint_rpy="${PI/2} 0 0"/>

    <link name="wheelturn_link">
      <visual>
	<origin xyz="0 0 0" rpy="0 0 0"/>
	<geometry>
	  <mesh filename="${wheelturn_mesh}"/>
	</geometry>
      </visual>

      <xacro:collision_cylinder radius="0.0675" length="0.002"/>

      <inertial>
        <mass value="0.2102" />
        <inertia ixx="2.56e-7" ixy="4.979e-7" ixz="2.425e-7" iyy="2.425e-7" iyz="3.745e-7" izz="6.657e-7"/>
      </inertial>
    </link>

    <joint name="base_footprint_wheelturn_joint" type="continuous">
      <axis xyz="0 0 1" rpy="0 0 ${PI}"/>
      <origin xyz="-0.09 0 0.015"/>
      <parent link="base_footprint"/>
      <child link="wheelturn_link"/>
    </joint>

    <xacro:wheel name="freewheel" parent="wheelturn_link" joint_xyz="-0.025 0 0.015" joint_rpy="${PI/2} 0 0"/>
      
    <link name="z_link">
      <visual>
	<origin xyz="0 0 0" rpy="0 0 ${PI/2}"/>
	<geometry>
	  <mesh filename="${z_mesh}"/>
	</geometry>
      </visual>

      <xacro:collision_cylinder radius="0.01" length="0.115"/>
      <xacro:collision_cylinder radius="0.025" length="0.085"/>

      <inertial>
        <mass value="0.092245" />
        <inertia ixx="5.697e-8" ixy="3.451e-8" ixz="5.343e-8" iyy="5.343e-8" iyz="3.451e-8" izz="3.451e-8" />
      </inertial>
    </link>

    <joint name="base_z_joint" type="revolute">
      <axis xyz="0 0 1" rpy="0 0 0"/>
      <origin xyz="0.0295 0.095 0.06" rpy="0 0 ${PI/2}"/>
      <parent link="base_link"/>
      <child link="z_link"/>
      <limit effort="${base_z_effort}" velocity="${base_z_vel}" lower="${base_z_lower}" upper="${base_z_upper}"/>
      <dynamics damping="0.7" friction="1.0"/>  
  </joint>

    <link name="lower_arm">
      <visual>
        <origin xyz="0 0 0" rpy="0 0 0"/>
        <geometry>
          <mesh filename="${lower_mesh}"/>
        </geometry>
      </visual>

      <xacro:collision_box size="0.168 0.01 0.01" xyz="0.09 0 0.0235"/>
      <xacro:collision_box size="0.168 0.01 0.01" xyz="0.09 0 -0.0235"/>
      <xacro:collision_box size="0.005 0.02 0.02" xyz="0.178 -0.025 0"/>
      <xacro:collision_cylinder radius="0.014" length="0.058" xyz="0 0 0" rpy="0 0 ${PI/2}"/>      
      <xacro:collision_cylinder radius="0.015" length="0.058" xyz="0.178 0 0" rpy="0 0 ${PI/2}"/>
      
      <inertial>
        <mass value="0.027199" />
        <inertia ixx="0.01" ixy="0" ixz="0" iyy="0.01" iyz="0" izz="0.01" />
      </inertial>
    </link>

    <joint name="z_lower_joint" type="revolute">
      <axis xyz="0 0 1" rpy="0 0 0"/>
      <origin xyz="0 0 0.025" rpy="${PI/2} -${PI/2} 0"/>
      <parent link="z_link"/>
      <child link="lower_arm"/>
      <limit effort="${z_lower_effort}" velocity="${z_lower_vel}" lower="${z_lower_lower}" upper="${z_lower_upper}"/>
      <dynamics damping="0.7" friction="1.0"/>
    </joint>

    <link name="upper_arm">
      <visual>
        <origin xyz="0 0 0" rpy="0 0 0"/>
        <geometry>
          <mesh filename="${upper_mesh}"/>
        </geometry>
      </visual>

      <xacro:collision_box size="0.174 0.01 0.01" xyz="0.0775 0 0.0235"/>
      <xacro:collision_box size="0.174 0.01 0.01" xyz="0.0775 0 -0.0235"/>
      <xacro:collision_box size="0.005 0.02 0.02" xyz="0 0.025 0"/>
      <xacro:collision_cylinder radius="0.015" length="0.058" xyz="0 0 0" rpy="0 0 ${PI/2}"/>      
      <xacro:collision_cylinder radius="0.015" length="0.011" xyz="0.178 0 0.0235" rpy="0 0 ${PI/2}"/>
      <xacro:collision_cylinder radius="0.015" length="0.011" xyz="0.178 0 -0.0235" rpy="0 0 ${PI/2}"/>
      
      <inertial>
        <mass value="0.05571" />
        <inertia ixx="0.01" ixy="0" ixz="2.975e-8" iyy="0.01" iyz="0" izz="0.01" />
      </inertial>
    </link>

    <joint name="lower_upper_joint" type="revolute">
      <axis xyz="0 0 1" rpy="0 0 0"/>
      <origin xyz="0.178 0 -0.059" rpy="0 0 0"/>
      <parent link="lower_arm"/>
      <child link="upper_arm"/>
      <limit effort="${lower_upper_effort}" velocity="${lower_upper_vel}" lower="${lower_upper_lower}" upper="${lower_upper_upper}"/>
      <dynamics damping="0.7" friction="1.0"/>
    </joint>
    
    <link name ="end_effector">
      <visual> 
        <origin xyz="0 0 0" rpy="0 0 0"/>
        <geometry>
          <mesh filename="${end_mesh}"/>
        </geometry>
      </visual>

      <xacro:collision_cylinder radius="0.015" length="0.0355" xyz="0 0 0" rpy="0 0 0"/>
      <xacro:collision_cylinder radius="0.01" length="0.043" xyz="0.006 0 0" rpy="0 ${PI/2} 0"/>

      <inertial>
        <mass value="0.19306" />
        <inertia ixx="0.01" ixy="2.919e-8" ixz="9.708e-8" iyy="0.01" iyz="9.034e-8" izz="0.01" />
      </inertial>
    </link>

    <joint name="upper_end_joint" type="revolute">
      <axis xyz="0 0 1" rpy="0 0 0"/>
      <origin xyz="0.178 0 0" rpy="0 0 0"/>
      <parent link="upper_arm"/>
      <child link="end_effector"/>
      <limit effort="${upper_end_effort}" velocity="${upper_end_vel}" lower="${upper_end_lower}" upper="${upper_end_upper}"/>
      <dynamics damping="0.7" friction="1.0"/>
    </joint>

    <link name="virtual_end">
      <visual>
        <origin xyz="0 0 -0.028" rpy="0 0 0" />
        <geometry>
          <box size="0.001 0.001 0.001" />
        </geometry>
      </visual>

      <xacro:collision_box size="0.001 0.001 0.001" xyz="0 0 -0.028"/>
      
      <inertial>
        <mass value="0.001" />
        <inertia ixx="0.001" ixy="0" ixz="0" iyy="0.001" iyz="0" izz="0.001" />
      </inertial>
    </link>

    <joint name="end_virtual_joint" type="fixed">
      <axis xyz="0 0 1" rpy="0 0 0"/>
      <origin xyz="0.028 0.0 0" rpy="${PI/2} 0 ${PI/2}"/>
      <parent link="end_effector"/>
      <child link="virtual_end"/>
      <limit effort="1000" velocity="0"/>
    </joint>

    <!-- camera models -->
    <xacro:camera_model name="camera_back_model" xyz="-0.16 0 0.1" rpy="0 -0.5 0"/>

    <xacro:camera_model name="camera_front_model" xyz="0.16 0 0.1" rpy="0 -0.5 ${PI}"/>

    <xacro:camera_model name="camera_side_model" xyz="0 -0.16 0.1" rpy="0 -0.5 ${PI/2}"/>
    
    <xacro:camera_model name="camera_outwards_model" xyz="0.165 0 0.1" rpy="0 0 0"/>
	
    <!-- Cameras for scene capturing -->

    <xacro:camera_rec name="camera_end" xyz="0.017 0.015 -0.0175" rpy="-${PI/2} 0 -0.4" parent="end_effector"/>
    <xacro:camera_rec name="camera_front" xyz="0.11 0 0.12" rpy="0 0.2 0" parent="base_link"/>
    <xacro:camera_rec name="camera_bird" xyz="0.75 -0.375 0.375" rpy="0 0.3 2.86" parent="base_link"/>
    <!-- Gazebo plugin publishing the ground truth odometry -->

    <xacro:gazebo_p3d/>
    
    <!-- Transmissions and plugin for ros_control -->

    <xacro:transmission_block joint_name="base_z_joint" interface_type="PositionJointInterface"/>
    <xacro:transmission_block joint_name="z_lower_joint" interface_type="PositionJointInterface"/> 
    <xacro:transmission_block joint_name="lower_upper_joint" interface_type="PositionJointInterface"/>
    <xacro:transmission_block joint_name="upper_end_joint" interface_type="PositionJointInterface"/>

    <xacro:ros_control_plugin ns="vacuum_bot"/>

  </xacro:macro>

  <xacro:vacuum_bot/>

</robot>

